<?xml version="1.0" encoding="utf-8"?>
<!-- =================================================================================== -->
<!-- |    This document was autogenerated by xacro from 4dof_4inchlow_robot.xacro      | -->
<!-- |    EDITING THIS FILE BY HAND IS NOT RECOMMENDED                                 | -->
<!-- =================================================================================== -->
<robot name="arm_demo">
  <!-- *************************** XACRO MACROS *************************** -->
  <!-- ************************* ROBOT DEFINITION ************************* -->
  <link name="world"/>
  <link name="shoulder_len">
    <visual>
      <origin rpy="0 0 0" xyz="0 .2475 0"/>
      <geometry>
        <box size="0.03 0.5 0.03"/>
      </geometry>
      <material name="silver">
        <color rgba="0.6 0.6 0.6 1"/>
      </material>
    </visual>
    <collision>
      <origin rpy="0 0 0" xyz="0 -.2475 0"/>
      <geometry>
        <box size="0.03 0.5 0.03"/>
      </geometry>
    </collision>
    <inertial>
      <origin rpy="0 0 0" xyz="0 .2475 0"/>
      <mass value="1.0"/>
      <inertia ixx=".021" ixy="0.0" ixz="0.0" iyy=".021" iyz="0.0" izz=".00015"/>
    </inertial>
  </link>
  <link name="body">
    <visual>
      <origin rpy="0 0 0" xyz=".09 0.2475 -.25"/>
      <geometry>
        <box size="0.25 0.32 .5"/>
      </geometry>
      <material name="silver">
        <color rgba="0.6 0.6 0.6 1"/>
      </material>
    </visual>
    <collision>
      <origin rpy="0 0 0" xyz=".09 0.2475 -.25"/>
      <geometry>
        <box size="0.18 0.32 0.5"/>
      </geometry>
    </collision>
    <inertial>
      <origin rpy="0 0 0" xyz=".09 .2475 -.25"/>
      <mass value="1.0"/>
      <inertia ixx=".112" ixy="0.0" ixz="0.0" iyy=".029" iyz="0.0" izz=".0235"/>
    </inertial>
  </link>
  <link name="head">
    <visual>
      <origin rpy="0 0 0" xyz=".09 0.2475 .09"/>
      <geometry>
        <sphere radius="0.09"/>
      </geometry>
      <material name="silver">
        <color rgba="0.6 0.6 0.6 1"/>
      </material>
    </visual>
    <collision>
      <origin rpy="0 0 0" xyz=".09 0.2475 .09"/>
      <geometry>
        <sphere radius="0.09"/>
      </geometry>
    </collision>
    <inertial>
      <origin rpy="0 0 0" xyz=".09 0.2475 .09"/>
      <mass value="1.0"/>
      <inertia ixx=".00324" ixy="0.0" ixz="0.0" iyy=".00324" iyz="0.0" izz=".00324"/>
    </inertial>
  </link>
  <link name="rodR">
    <visual>
      <origin rpy="0 0 0" xyz="0 .02 -.1"/>
      <geometry>
        <box size="0.03 0.03 0.2"/>
      </geometry>
      <material name="silver">
        <color rgba="0.6 0.6 0.6 1"/>
      </material>
    </visual>
    <collision>
      <origin rpy="0 0 0" xyz="0 -.025 -.1"/>
      <geometry>
        <box size="0.03 0.03 0.2"/>
      </geometry>
    </collision>
    <inertial>
      <origin rpy="0 0 0" xyz="0 -.025 -.1"/>
      <mass value="1.0"/>
      <inertia ixx=".0034" ixy="0.0" ixz="0.0" iyy=".0034" iyz="0.0" izz=".00015"/>
    </inertial>
  </link>
  <link name="rodL">
    <visual>
      <origin rpy="0 0 0" xyz="0 -.025 -.1"/>
      <geometry>
        <box size="0.03 0.03 0.2"/>
      </geometry>
      <material name="silver">
        <color rgba="0.6 0.6 0.6 1"/>
      </material>
    </visual>
    <collision>
      <origin rpy="0 0 0" xyz="0 -.025 -.1"/>
      <geometry>
        <box size="0.03 0.03 0.2"/>
      </geometry>
    </collision>
    <inertial>
      <origin rpy="0 0 0" xyz="0 -.025 -.1"/>
      <mass value="1.0"/>
      <inertia ixx=".0034" ixy="0.0" ixz="0.0" iyy=".0034" iyz="0.0" izz=".00015"/>
    </inertial>
  </link>
  <joint name="right_arm" type="fixed">
    <parent link="world"/>
    <child link="rodR"/>
    <origin rpy="0 0 0" xyz="-.34 0.03 0.5"/>
  </joint>
  <joint name="left_arm" type="fixed">
    <parent link="world"/>
    <child link="rodL"/>
    <origin rpy="0 0 0" xyz="-.34 0.475 0.5"/>
  </joint>
  <joint name="base_base" type="fixed">
    <parent link="world"/>
    <child link="motor1/INPUT_INTERFACE"/>
    <origin rpy="0 0 0" xyz="0 0.03 0.2984"/>
  </joint>
  <joint name="base_s" type="fixed">
    <parent link="world"/>
    <child link="ms1/INPUT_INTERFACE"/>
    <origin rpy="0 0 0" xyz="0 0.03 0.2984"/>
  </joint>
  <joint name="shoulder" type="fixed">
    <parent link="world"/>
    <child link="shoulder_len"/>
    <origin rpy="0 0 0" xyz="-.34 0 0.5"/>
  </joint>
  <joint name="body" type="fixed">
    <parent link="world"/>
    <child link="body"/>
    <origin rpy="0 0 0" xyz="-.34 0 0.515"/>
  </joint>
  <joint name="head" type="fixed">
    <parent link="world"/>
    <child link="head"/>
    <origin rpy="0 0 0" xyz="-.318 0 0.5"/>
  </joint>
  <link name="motor1/INPUT_INTERFACE">
    <visual>
      <origin rpy="0 0 0" xyz="0 0 0"/>
      <geometry>
        <mesh filename="package://hebi_description/meshes/X5.stl" scale="0.001 0.001 0.001"/>
      </geometry>
      <material name="red">
        <color rgba=".82 0.06 0.06 1"/>
      </material>
    </visual>
    <collision>
      <origin rpy="0 0 0" xyz="0 0 0"/>
      <geometry>
        <mesh filename="package://hebi_description/meshes/X5.stl" scale="0.001 0.001 0.001"/>
      </geometry>
    </collision>
    <inertial>
      <origin rpy="0 0 0" xyz="-0.0142 -0.0031 0.0165"/>
      <mass value="0.322"/>
      <mass value="0.360"/>
      <inertia ixx="0.00015" ixy="0.0000341" ixz="0.0000118" iyy="0.000255" iyz="0.00000229" izz="0.000350"/>
    </inertial>
  </link>
  <joint name="motor1/X5_9" type="continuous">
    <parent link="motor1/INPUT_INTERFACE"/>
    <child link="right_arm1/INPUT_INTERFACE"/>
    <origin rpy="0 0 0" xyz="0 0 0.031"/>
    <axis xyz="0 0 1"/>
    <limit effort="13.0" velocity="14"/>
    <dynamics damping="0.1" friction="0.1"/>
  </joint>
  <gazebo reference="motor1/INPUT_INTERFACE">
    <selfCollide>true</selfCollide>
    <gravity>true</gravity>
    <sensor name="motor1/imu_sensor" type="imu">
      <always_on>true</always_on>
      <update_rate>100</update_rate>
      <visualize>true</visualize>
      <plugin filename="libgazebo_imu_sensor.so" name="imu_plugin">
        <topicName>/hebi_gazebo_plugin/imu/motor1</topicName>
        <bodyName>motor1/imu_link</bodyName>
        <updateRateHZ>10.0</updateRateHZ>
        <gaussianNoise>0.0</gaussianNoise>
        <xyzOffset>0.025 0 0.003</xyzOffset>
        <rpyOffset>0 0 0</rpyOffset>
        <frameName>motor1/imu_link</frameName>
      </plugin>
      <pose>0 0 0 0 0 0</pose>
    </sensor>
  </gazebo>
  <link name="ms1/INPUT_INTERFACE">
    <visual>
      <origin rpy="0 0 0" xyz="0 0 0"/>
      <geometry>
        <mesh filename="package://hebi_description/meshes/A-2039-02.stl"/>
      </geometry>
      <material name="black">
        <color rgba="0 0 0 1"/>
      </material>
    </visual>
    <visual>
      <origin rpy="0 1.57075 0" xyz="-0.2 0.02 0"/>
      <geometry>
        <cylinder length="0.3746" radius=".016"/>
      </geometry>
      <material name="silver">
        <color rgba="0.6 0.6 0.6 1"/>
      </material>
    </visual>
    <collision>
      <origin rpy="0 1.57079632679 0" xyz="0 0 0"/>
      <geometry>
        <mesh filename="package://hebi_description/meshes/A-2038-02.stl"/>
      </geometry>
    </collision>
    <collision>
      <origin rpy="0 1.57075 0" xyz="0.2 -0.02 0"/>
      <geometry>
        <cylinder length="0.3746" radius=".016"/>
      </geometry>
    </collision>
    <collision>
      <origin rpy="0 0 0" xyz="0.4 0.0 0.04"/>
      <geometry>
        <mesh filename="package://hebi_description/meshes/A-2039-02.stl"/>
      </geometry>
    </collision>
    <!-- Approximate inertia as thin rod about x axis -->
    <inertial>
      <origin rpy="0 0 0" xyz="0.2 0 0.02"/>
      <mass value="0.432"/>
      <inertia ixx="0.0" ixy="0.0" ixz="0.0" iyy="0.00576" iyz="0.0" izz="0.00576"/>
    </inertial>
  </link>
  <gazebo reference="ms1/INPUT_INTERFACE">
    <selfCollide>true</selfCollide>
  </gazebo>
  <link name="right_arm1/INPUT_INTERFACE">
    <visual>
      <origin rpy="0 0 0" xyz="0 0 0"/>
      <geometry>
        <mesh filename="package://hebi_description/meshes/A-2038-02.stl"/>
      </geometry>
      <material name="black">
        <color rgba="0 0 0 1"/>
      </material>
    </visual>
    <visual>
      <origin rpy="0 1.57075 0" xyz="0.0625 0 0.02"/>
      <geometry>
        <cylinder length="0.0996" radius=".016"/>
      </geometry>
      <material name="silver">
        <color rgba="0.6 0.6 0.6 1"/>
      </material>
    </visual>
    <visual>
      <origin rpy="1.3343 0 0" xyz="0.125 -0.0194432968708 0.0246859584714"/>
      <geometry>
        <mesh filename="package://hebi_description/meshes/A-2039-02.stl"/>
      </geometry>
      <material name="black">
        <color rgba="0 0 0 1"/>
      </material>
    </visual>
    <collision>
      <origin rpy="0 0 0" xyz="0 0 0"/>
      <geometry>
        <mesh filename="package://hebi_description/meshes/A-2038-02.stl"/>
      </geometry>
    </collision>
    <collision>
      <origin rpy="0 1.57075 0" xyz="0.0625 0 0.02"/>
      <geometry>
        <cylinder length="0.0996" radius=".016"/>
      </geometry>
    </collision>
    <collision>
      <origin rpy="1.3343 0 0" xyz="0.125 -0.0194432968708 0.0246859584714"/>
      <geometry>
        <mesh filename="package://hebi_description/meshes/A-2039-02.stl"/>
      </geometry>
    </collision>
    <!-- Approximate inertia as thin rod about x axis -->
    <inertial>
      <origin rpy="0 0 0" xyz="0.0625 0 0.02"/>
      <mass value="0.322"/>
      <inertia ixx="0.0" ixy="0.0" ixz="0.0" iyy="0.000419270833333" iyz="0.0" izz="0.000419270833333"/>
    </inertial>
  </link>
  <joint name="right_arm1/OUTPUT_JOINT" type="fixed">
    <parent link="right_arm1/INPUT_INTERFACE"/>
    <child link="motor2/INPUT_INTERFACE"/>
    <origin rpy="1.3343 0 0" xyz="0.125 -0.0194432968708 0.0246859584714"/>
  </joint>
  <gazebo reference="right_arm1/INPUT_INTERFACE">
    <selfCollide>true</selfCollide>
  </gazebo>
  <link name="motor2/INPUT_INTERFACE">
    <visual>
      <origin rpy="0 0 0" xyz="0 0 0"/>
      <geometry>
        <mesh filename="package://hebi_description/meshes/X5.stl" scale="0.001 0.001 0.001"/>
      </geometry>
      <material name="red">
        <color rgba=".82 0.06 0.06 1"/>
      </material>
    </visual>
    <collision>
      <origin rpy="0 0 0" xyz="0 0 0"/>
      <geometry>
        <mesh filename="package://hebi_description/meshes/X5.stl" scale="0.001 0.001 0.001"/>
      </geometry>
    </collision>
    <inertial>
      <origin rpy="0 0 0" xyz="-0.0142 -0.0031 0.0165"/>
      <mass value="0.322"/>
      <mass value="0.360"/>
      <inertia ixx="0.00015" ixy="0.0000341" ixz="0.0000118" iyy="0.000255" iyz="0.00000229" izz="0.000350"/>
    </inertial>
  </link>
  <joint name="motor2/X5_9" type="continuous">
    <parent link="motor2/INPUT_INTERFACE"/>
    <child link="right_arm2/INPUT_INTERFACE"/>
    <origin rpy="0 0 0" xyz="0 0 0.031"/>
    <axis xyz="0 0 1"/>
    <limit effort="13.0" velocity="14"/>
    <dynamics damping="0.1" friction="0.1"/>
  </joint>
  <gazebo reference="motor2/INPUT_INTERFACE">
    <selfCollide>true</selfCollide>
    <gravity>true</gravity>
    <sensor name="motor2/imu_sensor" type="imu">
      <always_on>true</always_on>
      <update_rate>100</update_rate>
      <visualize>true</visualize>
      <plugin filename="libgazebo_imu_sensor.so" name="imu_plugin">
        <topicName>/hebi_gazebo_plugin/imu/motor2</topicName>
        <bodyName>motor2/imu_link</bodyName>
        <updateRateHZ>10.0</updateRateHZ>
        <gaussianNoise>0.0</gaussianNoise>
        <xyzOffset>0.025 0 0.003</xyzOffset>
        <rpyOffset>0 0 0</rpyOffset>
        <frameName>motor2/imu_link</frameName>
      </plugin>
      <pose>0 0 0 0 0 0</pose>
    </sensor>
  </gazebo>
  <link name="right_arm2/INPUT_INTERFACE">
    <visual>
      <origin rpy="0 0 0" xyz="0 0 0"/>
      <geometry>
        <mesh filename="package://hebi_description/meshes/A-2038-02.stl"/>
      </geometry>
      <material name="black">
        <color rgba="0 0 0 1"/>
      </material>
    </visual>
    <visual>
      <origin rpy="0 1.57075 0" xyz="0.0846 0 0.02"/>
      <geometry>
        <cylinder length="0.1438" radius=".016"/>
      </geometry>
      <material name="silver">
        <color rgba="0.6 0.6 0.6 1"/>
      </material>
    </visual>
    <visual>
      <origin rpy="2.163 0 0" xyz="0.1692 -0.0165942524924 0.00883618415505"/>
      <geometry>
        <mesh filename="package://hebi_description/meshes/A-2039-02.stl"/>
      </geometry>
      <material name="black">
        <color rgba="0 0 0 1"/>
      </material>
    </visual>
    <collision>
      <origin rpy="0 0 0" xyz="0 0 0"/>
      <geometry>
        <mesh filename="package://hebi_description/meshes/A-2038-02.stl"/>
      </geometry>
    </collision>
    <collision>
      <origin rpy="0 1.57075 0" xyz="0.0846 0 0.02"/>
      <geometry>
        <cylinder length="0.1438" radius=".016"/>
      </geometry>
    </collision>
    <collision>
      <origin rpy="2.163 0 0" xyz="0.1692 -0.0165942524924 0.00883618415505"/>
      <geometry>
        <mesh filename="package://hebi_description/meshes/A-2039-02.stl"/>
      </geometry>
    </collision>
    <!-- Approximate inertia as thin rod about x axis -->
    <inertial>
      <origin rpy="0 0 0" xyz="0.0846 0 0.02"/>
      <mass value="0.33968"/>
      <inertia ixx="0.0" ixy="0.0" ixz="0.0" iyy="0.0008103813696" iyz="0.0" izz="0.0008103813696"/>
    </inertial>
  </link>
  <joint name="right_arm2/OUTPUT_JOINT" type="fixed">
    <parent link="right_arm2/INPUT_INTERFACE"/>
    <child link="motor3/INPUT_INTERFACE"/>
    <origin rpy="2.163 0 0" xyz="0.1692 -0.0165942524924 0.00883618415505"/>
  </joint>
  <gazebo reference="right_arm2/INPUT_INTERFACE">
    <selfCollide>true</selfCollide>
  </gazebo>
  <link name="motor3/INPUT_INTERFACE">
    <visual>
      <origin rpy="0 0 0" xyz="0 0 0"/>
      <geometry>
        <mesh filename="package://hebi_description/meshes/X5.stl" scale="0.001 0.001 0.001"/>
      </geometry>
      <material name="red">
        <color rgba=".82 0.06 0.06 1"/>
      </material>
    </visual>
    <collision>
      <origin rpy="0 0 0" xyz="0 0 0"/>
      <geometry>
        <mesh filename="package://hebi_description/meshes/X5.stl" scale="0.001 0.001 0.001"/>
      </geometry>
    </collision>
    <inertial>
      <origin rpy="0 0 0" xyz="-0.0142 -0.0031 0.0165"/>
      <mass value="0.322"/>
      <mass value="0.360"/>
      <inertia ixx="0.00015" ixy="0.0000341" ixz="0.0000118" iyy="0.000255" iyz="0.00000229" izz="0.000350"/>
    </inertial>
  </link>
  <joint name="motor3/X5_9" type="continuous">
    <parent link="motor3/INPUT_INTERFACE"/>
    <child link="right_arm3/INPUT_INTERFACE"/>
    <origin rpy="0 0 0" xyz="0 0 0.031"/>
    <axis xyz="0 0 1"/>
    <limit effort="13.0" velocity="14"/>
    <dynamics damping="0.1" friction="0.1"/>
  </joint>
  <gazebo reference="motor3/INPUT_INTERFACE">
    <selfCollide>true</selfCollide>
    <gravity>true</gravity>
    <sensor name="motor3/imu_sensor" type="imu">
      <always_on>true</always_on>
      <update_rate>100</update_rate>
      <visualize>true</visualize>
      <plugin filename="libgazebo_imu_sensor.so" name="imu_plugin">
        <topicName>/hebi_gazebo_plugin/imu/motor3</topicName>
        <bodyName>motor3/imu_link</bodyName>
        <updateRateHZ>10.0</updateRateHZ>
        <gaussianNoise>0.0</gaussianNoise>
        <xyzOffset>0.025 0 0.003</xyzOffset>
        <rpyOffset>0 0 0</rpyOffset>
        <frameName>motor3/imu_link</frameName>
      </plugin>
      <pose>0 0 0 0 0 0</pose>
    </sensor>
  </gazebo>
  <link name="right_arm3/INPUT_INTERFACE">
    <visual>
      <origin rpy="0 0 0" xyz="0 0 0"/>
      <geometry>
        <mesh filename="package://hebi_description/meshes/A-2038-02.stl"/>
      </geometry>
      <material name="black">
        <color rgba="0 0 0 1"/>
      </material>
    </visual>
    <visual>
      <origin rpy="0 1.57075 0" xyz="0.1024 0 0.02"/>
      <geometry>
        <cylinder length="0.1794" radius=".016"/>
      </geometry>
      <material name="silver">
        <color rgba="0.6 0.6 0.6 1"/>
      </material>
    </visual>
    <visual>
      <origin rpy="-3.7736 0 0" xyz="0.2048 -0.0118153112202 0.00386313472914"/>
      <geometry>
        <mesh filename="package://hebi_description/meshes/A-2039-02.stl"/>
      </geometry>
      <material name="black">
        <color rgba="0 0 0 1"/>
      </material>
    </visual>
    <collision>
      <origin rpy="0 0 0" xyz="0 0 0"/>
      <geometry>
        <mesh filename="package://hebi_description/meshes/A-2038-02.stl"/>
      </geometry>
    </collision>
    <collision>
      <origin rpy="0 1.57075 0" xyz="0.1024 0 0.02"/>
      <geometry>
        <cylinder length="0.1794" radius=".016"/>
      </geometry>
    </collision>
    <collision>
      <origin rpy="-3.7736 0 0" xyz="0.2048 -0.0118153112202 0.00386313472914"/>
      <geometry>
        <mesh filename="package://hebi_description/meshes/A-2039-02.stl"/>
      </geometry>
    </collision>
    <!-- Approximate inertia as thin rod about x axis -->
    <inertial>
      <origin rpy="0 0 0" xyz="0.1024 0 0.02"/>
      <mass value="0.35392"/>
      <inertia ixx="0.0" ixy="0.0" ixz="0.0" iyy="0.00123704005973" iyz="0.0" izz="0.00123704005973"/>
    </inertial>
  </link>
  <joint name="right_arm3/OUTPUT_JOINT" type="fixed">
    <parent link="right_arm3/INPUT_INTERFACE"/>
    <child link="motor4/INPUT_INTERFACE"/>
    <origin rpy="-3.7736 0 0" xyz="0.2048 -0.0118153112202 0.00386313472914"/>
  </joint>
  <gazebo reference="right_arm3/INPUT_INTERFACE">
    <selfCollide>true</selfCollide>
  </gazebo>
  <link name="motor4/INPUT_INTERFACE">
    <visual>
      <origin rpy="0 0 0" xyz="0 0 0"/>
      <geometry>
        <mesh filename="package://hebi_description/meshes/X5.stl" scale="0.001 0.001 0.001"/>
      </geometry>
      <material name="red">
        <color rgba=".82 0.06 0.06 1"/>
      </material>
    </visual>
    <collision>
      <origin rpy="0 0 0" xyz="0 0 0"/>
      <geometry>
        <mesh filename="package://hebi_description/meshes/X5.stl" scale="0.001 0.001 0.001"/>
      </geometry>
    </collision>
    <inertial>
      <origin rpy="0 0 0" xyz="-0.0142 -0.0031 0.0165"/>
      <mass value="0.322"/>
      <mass value="0.335"/>
      <inertia ixx="0.00015" ixy="0.0000341" ixz="0.0000118" iyy="0.000255" iyz="0.00000229" izz="0.000350"/>
    </inertial>
  </link>
  <joint name="motor4/X5_4" type="continuous">
    <parent link="motor4/INPUT_INTERFACE"/>
    <child link="sensor/INPUT_INTERFACE"/>
    <origin rpy="0 0 0" xyz="0 0 0.031"/>
    <axis xyz="0 0 1"/>
    <limit effort="7.0" velocity="32"/>
    <dynamics damping="0.1" friction="0.1"/>
  </joint>
  <gazebo reference="motor4/INPUT_INTERFACE">
    <selfCollide>true</selfCollide>
    <gravity>true</gravity>
    <sensor name="motor4/imu_sensor" type="imu">
      <always_on>true</always_on>
      <update_rate>100</update_rate>
      <visualize>true</visualize>
      <plugin filename="libgazebo_imu_sensor.so" name="imu_plugin">
        <topicName>/hebi_gazebo_plugin/imu/motor4</topicName>
        <bodyName>motor4/imu_link</bodyName>
        <updateRateHZ>10.0</updateRateHZ>
        <gaussianNoise>0.0</gaussianNoise>
        <xyzOffset>0.025 0 0.003</xyzOffset>
        <rpyOffset>0 0 0</rpyOffset>
        <frameName>motor4/imu_link</frameName>
      </plugin>
      <pose>0 0 0 0 0 0</pose>
    </sensor>
  </gazebo>
  <link name="sensor/INPUT_INTERFACE">
    <visual>
      <origin rpy="0 0 0" xyz="0 0 0"/>
      <geometry>
        <mesh filename="package://hebi_description/meshes/A-2038-02.stl"/>
      </geometry>
      <material name="black">
        <color rgba="0 0 0 1"/>
      </material>
    </visual>
    <visual>
      <origin rpy="0 1.57075 0" xyz="0.0967 0 0.02"/>
      <geometry>
        <cylinder length="0.168" radius=".016"/>
      </geometry>
      <material name="silver">
        <color rgba="0.6 0.6 0.6 1"/>
      </material>
    </visual>
    <visual>
      <origin rpy="0 0 0" xyz="0.1984 0 0.02"/>
      <geometry>
        <sphere radius="0.023"/>
      </geometry>
      <material name="silver">
        <color rgba="0.6 0.6 0.6 1"/>
      </material>
    </visual>
    <collision>
      <origin rpy="0 0 0" xyz="0 0 0"/>
      <geometry>
        <mesh filename="package://hebi_description/meshes/A-2038-02.stl"/>
      </geometry>
    </collision>
    <collision>
      <origin rpy="0 1.57075 0" xyz="0.0967 0 0.02"/>
      <geometry>
        <cylinder length="0.168" radius=".016"/>
      </geometry>
    </collision>
    <collision>
      <origin rpy="0 0 0" xyz="0.1934 0 0.02"/>
      <geometry>
        <sphere radius="0.02"/>
      </geometry>
    </collision>
    <!-- Approximate inertia as thin rod about x axis -->
    <inertial>
      <origin rpy="0 0 0" xyz="0.0967 0 0.02"/>
      <mass value="0.34936"/>
      <inertia ixx="0.0" ixy="0.0" ixz="0.0" iyy="0.00108894231013" iyz="0.0" izz="0.00108894231013"/>
    </inertial>
  </link>
  <joint name="end_joint" type="fixed">
    <parent link="sensor/INPUT_INTERFACE"/>
    <child link="end_link/INPUT_INTERFACE"/>
    <origin rpy="0 0 0" xyz="0.1934 0 0.02"/>
  </joint>
  <gazebo reference="sensor/INPUT_INTERFACE">
    <selfCollide>true</selfCollide>
  </gazebo>
  <!-- end link -->
  <link name="end_link/INPUT_INTERFACE">
  </link>
  <gazebo reference="base">
    <selfCollide>true</selfCollide>
  </gazebo>
  <gazebo>
    <plugin filename="libhebi_gazebo_plugin.so" name="hebi_gazebo_plugin">
    </plugin>
  </gazebo>
</robot>

